Workbook

Sheet Lisez-moi
B1: SIMULATEUR DE LA GRILLE DE NOTATION
B2: Groupe BCP — modèle de notation interne des entreprises (TPE, PME, grandes entreprises). Outil pédagogique : seuls les résultats de l'outil de notation font foi.
B4: À quoi il sert | C4: Comprendre comment la note se construit : simuler un dossier, voir l'effet d'un ratio, d'une donnée manquante, d'une exception ou d'un défaut, et rejouer les cas présentés au management.
B5: Onglet Simulateur | C5: 1) Choisissez « Saisie libre » ou un cas exemple (cellule D4). 2) Renseignez le cadrage et les 45 critères. 3) Lisez le résultat en haut à droite : statut, grade final, score brut, couverture, exceptions, support groupe.
B6: Saisir un critère | C6: Ratio : la valeur, dans l'unité indiquée (ex. 30 pour 30 %, 1,4 pour 1,4x, 20 pour 20 jours). Qualitatif : le repère 100, 75, 50, 25 ou 0 ; son libellé s'affiche dans la dernière colonne, et tous les repères sont dans l'onglet Grille.
B7: Statut d'une donnée | C7: Disponible : observée, compte dans la couverture. Estimée : compte dans le score, pas dans la couverture. Manquante (ou valeur vide) : score prudent de 25, pas dans la couverture ; une donnée critique manquante (D1.4, D1.5, D3.1) empêche toute notation.
B8: Ordre du calcul | C8: Score de chaque critère → poids du segment (le poids d'un critère ESG non matériel passe à son critère receveur) → score brut = moyenne pondérée → défaut constaté ? (grade DEF) → porte de qualité (60 % du poids observé, 30 % par domaine, confiance au moins C) → grade issu du score → exceptions (plafonds) → support groupe (2 crans au plus, si les 4 conditions sont réunies).
B9: Légende des couleurs | C9: Fond orangé, texte bleu : cellule à saisir. Fond crème : calcul. Score en vert : 75 ou plus ; en rouge : 25 ou moins. Les onglets Paramètres et Grille reprennent les valeurs du modèle et peuvent être modifiés pour tester une sensibilité.
B10: Ce que le simulateur ne fait pas | C10: Segmentation automatique à partir du chiffre d'affaires (le segment est choisi), cas particuliers de certains ratios, contrôles de cohérence et explications détaillées, conversion des devises, circuit de validation. Il ne remplace pas l'outil.
B11: Contrôle | C11: Les cinq cas exemples ont été calculés par le moteur de l'outil ; en les chargeant, la ligne « Contrôle » du simulateur affiche « concordant » quand le simulateur retrouve le même grade.

Sheet Simulateur
B1: SIMULATEUR DE NOTATION — MODÈLE STANDARD ENTREPRISES
B2: Modèle CORP_STD_V1 v3.0.0. Saisissez dans les cellules sur fond orangé (texte bleu), ou chargez un cas exemple. Les calculs reproduisent le moteur de l'outil ; seuls les résultats de l'outil font foi.
B4: Cas chargé | D4: Saisie libre | E4: « Saisie libre » : vos saisies sont utilisées. Un cas exemple remplace toutes les saisies par celles du cas (colonne « Retenu »). | S4: =IF($D$4="Saisie libre",0,MATCH($D$4,'Cas exemples'!$D$4:$H$4,0)) -> 0
S5: =MATCH($F$9,{"TPE","PME","GE"},0) -> 2
B6: 1. Cadrage du dossier
B7: Élément | E7: Saisie | F7: Retenu | I7: Résultat | M7: Valeur
B8: Contrepartie | E8: Entreprise exemple | F8: =IF($S$4=0,E8,INDEX('Cas exemples'!$D$6:$H$6,1,$S$4)) -> Entreprise exemple | I8: Statut de la notation | M8: =IF($F$22="Oui","Défaut constaté : le grade de défaut s'impose, quel que soit le score",IF(SUMPRODUCT(($G$34:$G$78="Oui")*($X$34:$X$78=1)*($Y$34:$Y$78=0))>0,"Pas de notation : donnée critique manquante",IF(NOT(AND($M$12>=Paramètres!$C$6,COUNTIF($I$83:$I$89,"Oui")=0,IF(($F$12*Paramètres!$C$8+$F$13*Paramètres!$C$9+$F$14*Paramètres!$C$10+$F$15*Paramètres!$C$11)>=Paramètres!$C$12,"A",IF(($F$12*Paramètres!$C$8+$F$13*Paramètres!$C$9+$F$14*Paramètres!$C$10+$F$15*Paramètres!$C$11)>=Paramètres!$C$13,"B",IF(($F$12*Paramètres!$C$8+$F$13*Paramètres!$C$9+$F$14*Paramètres!$C$10+$F$15*Paramètres!$C$11)>=Paramètres!$C$14,"C","U")))<>"U")),"Pas de grade : information insuffisante (compléter le dossier)","Noté"))) -> Noté
B9: Segment (TPE, PME, GE) | E9: PME | F9: =IF($S$4=0,E9,INDEX('Cas exemples'!$D$7:$H$7,1,$S$4)) -> PME | I9: Grade final | M9: =IF(SUMPRODUCT(($G$34:$G$78="Oui")*($X$34:$X$78=1)*($Y$34:$Y$78=0))>0,IF($F$22="Oui",$F$23,"Aucun grade"),IF($F$22="Oui",$F$23,IF(NOT(AND($M$12>=Paramètres!$C$6,COUNTIF($I$83:$I$89,"Oui")=0,IF(($F$12*Paramètres!$C$8+$F$13*Paramètres!$C$9+$F$14*Paramètres!$C$10+$F$15*Paramètres!$C$11)>=Paramètres!$C$12,"A",IF(($F$12*Paramètres!$C$8+$F$13*Paramètres!$C$9+$F$14*Paramètres!$C$10+$F$15*Paramètres!$C$11)>=Paramètres!$C$13,"B",IF(($F$12*Paramètres!$C$8+$F$13*Paramètres!$C$9+$F$14*Paramètres!$C$10+$F$15*Paramètres!$C$11)>=Paramètres!$C$14,"C","U")))<>"U")),"Aucun grade",IF(AND($F$24="Oui",AND($F$25="Oui",$F$26="Oui",$F$27="Oui",$F$28="Oui")),INDEX(Paramètres!$B$20:$B$27,MAX(1,MATCH($M$17,Paramètres!$B$20:$B$27,0)-MIN($F$29,Paramètres!$C$15))),$M$17)))) -> STD-P3
B10: Risque climatique physique matériel ? (sinon D7.1 écarté, poids vers D7.3) | E10: Non | F10: =IF($S$4=0,E10,INDEX('Cas exemples'!$D$8:$H$8,1,$S$4)) -> Non | I10: Score brut (0 à 100) | M10: =IF(OR(SUM($N$34:$N$78)=0,SUMPRODUCT(($G$34:$G$78="Oui")*($X$34:$X$78=1)*($Y$34:$Y$78=0))>0),"—",SUM($Z$34:$Z$78)/SUM($N$34:$N$78)) -> 81
B11: Risque de transition matériel ? (sinon D7.2 écarté, poids vers D7.4) | E11: Non | F11: =IF($S$4=0,E11,INDEX('Cas exemples'!$D$9:$H$9,1,$S$4)) -> Non | I11: Grade issu du score | M11: =IF(AND(ISNUMBER($M$10),OR($F$22="Oui",AND($M$12>=Paramètres!$C$6,COUNTIF($I$83:$I$89,"Oui")=0,IF(($F$12*Paramètres!$C$8+$F$13*Paramètres!$C$9+$F$14*Paramètres!$C$10+$F$15*Paramètres!$C$11)>=Paramètres!$C$12,"A",IF(($F$12*Paramètres!$C$8+$F$13*Paramètres!$C$9+$F$14*Paramètres!$C$10+$F$15*Paramètres!$C$11)>=Paramètres!$C$13,"B",IF(($F$12*Paramètres!$C$8+$F$13*Paramètres!$C$9+$F$14*Paramètres!$C$10+$F$15*Paramètres!$C$11)>=Paramètres!$C$14,"C","U")))<>"U"))),INDEX(Paramètres!$B$20:$B$27,MATCH(1,INDEX(($M$10>=Paramètres!$C$20:$C$27)*1,0),0)),"—") -> STD-P3
B12: Confiance — complétude du dossier (0 à 100) | E12: 100 | F12: =IF($S$4=0,E12,INDEX('Cas exemples'!$D$10:$H$10,1,$S$4)) -> 100 | I12: Couverture observée (minimum 60 %) | M12: =IF(SUM($N$34:$N$78)=0,0,SUM($O$34:$O$78)/SUM($N$34:$N$78)) -> 1
B13: Confiance — fraîcheur des données | E13: 100 | F13: =IF($S$4=0,E13,INDEX('Cas exemples'!$D$11:$H$11,1,$S$4)) -> 100 | I13: Domaines sous le seuil de couverture | M13: =IF(COUNTIF($I$83:$I$89,"Oui")=0,"Aucun",_xlfn.TEXTJOIN(", ",TRUE(),IF(I83="Oui",B83,""),IF(I84="Oui",B84,""),IF(I85="Oui",B85,""),IF(I86="Oui",B86,""),IF(I87="Oui",B87,""),IF(I88="Oui",B88,""),IF(I89="Oui",B89,""))) -> Aucun
B14: Confiance — fiabilité des sources | E14: 75 | F14: =IF($S$4=0,E14,INDEX('Cas exemples'!$D$12:$H$12,1,$S$4)) -> 75 | I14: Confiance (score / classe) | M14: =FIXED(($F$12*Paramètres!$C$8+$F$13*Paramètres!$C$9+$F$14*Paramètres!$C$10+$F$15*Paramètres!$C$11),2)&" — classe "&IF(($F$12*Paramètres!$C$8+$F$13*Paramètres!$C$9+$F$14*Paramètres!$C$10+$F$15*Paramètres!$C$11)>=Paramètres!$C$12,"A",IF(($F$12*Paramètres!$C$8+$F$13*Paramètres!$C$9+$F$14*Paramètres!$C$10+$F$15*Paramètres!$C$11)>=Paramètres!$C$13,"B",IF(($F$12*Paramètres!$C$8+$F$13*Paramètres!$C$9+$F$14*Paramètres!$C$10+$F$15*Paramètres!$C$11)>=Paramètres!$C$14,"C","U"))) -> 88.75 — classe A
B15: Confiance — provenance (certifiée, déclarative…) | E15: 75 | F15: =IF($S$4=0,E15,INDEX('Cas exemples'!$D$13:$H$13,1,$S$4)) -> 75 | I15: Données critiques manquantes | M15: =IF(SUMPRODUCT(($G$34:$G$78="Oui")*($X$34:$X$78=1)*($Y$34:$Y$78=0))=0,"Aucune",SUMPRODUCT(($G$34:$G$78="Oui")*($X$34:$X$78=1)*($Y$34:$Y$78=0))&" critère(s) critique(s) : notation impossible") -> Aucune
B16: Exception NC01 — Couverture du service de la dette inférieure à 1 en scénario de base | E16: Non | F16: =IF($S$4=0,E16,INDEX('Cas exemples'!$D$14:$H$14,1,$S$4)) -> Non | I16: Exceptions appliquées | M16: =IF(($F$16="Oui")+($F$17="Oui")+($F$18="Oui")+($F$19="Oui")=0,"Aucune",_xlfn.TEXTJOIN(", ",TRUE(),IF($F$16="Oui","NC01 (plafond "&Paramètres!$C$31&")",""),IF($F$17="Oui","NC02 (plafond "&Paramètres!$C$32&")",""),IF($F$18="Oui","NC03 (plafond "&Paramètres!$C$33&")",""),IF($F$19="Oui","NC04 (plafond "&Paramètres!$C$34&")",""))) -> Aucune
B17: Exception NC02 — Incertitude matérielle sur la continuité d'exploitation | E17: Non | F17: =IF($S$4=0,E17,INDEX('Cas exemples'!$D$15:$H$15,1,$S$4)) -> Non | I17: Note autonome (après exceptions) | M17: =IF(OR(SUMPRODUCT(($G$34:$G$78="Oui")*($X$34:$X$78=1)*($Y$34:$Y$78=0))>0,$F$22="Oui",NOT(AND($M$12>=Paramètres!$C$6,COUNTIF($I$83:$I$89,"Oui")=0,IF(($F$12*Paramètres!$C$8+$F$13*Paramètres!$C$9+$F$14*Paramètres!$C$10+$F$15*Paramètres!$C$11)>=Paramètres!$C$12,"A",IF(($F$12*Paramètres!$C$8+$F$13*Paramètres!$C$9+$F$14*Paramètres!$C$10+$F$15*Paramètres!$C$11)>=Paramètres!$C$13,"B",IF(($F$12*Paramètres!$C$8+$F$13*Paramètres!$C$9+$F$14*Paramètres!$C$10+$F$15*Paramètres!$C$11)>=Paramètres!$C$14,"C","U")))<>"U"))),"—",INDEX(Paramètres!$B$20:$B$27,MAX(MATCH($M$11,Paramètres!$B$20:$B$27,0),IF($F$16="Oui",MATCH(Paramètres!$C$31,Paramètres!$B$20:$B$27,0),0),IF($F$17="Oui",MATCH(Paramètres!$C$32,Paramètres!$B$20:$B$27,0),0),IF($F$18="Oui",MATCH(Paramètres!$C$33,Paramètres!$B$20:$B$27,0),0),IF($F$19="Oui",MATCH(Paramètres!$C$34,Paramètres!$B$20:$B$27,0),0)))) -> STD-P3
B18: Exception NC03 — Excédent brut d'exploitation négatif deux années sur trois | E18: Non | F18: =IF($S$4=0,E18,INDEX('Cas exemples'!$D$16:$H$16,1,$S$4)) -> Non | I18: Support groupe | M18: =IF($F$24<>"Oui","Non demandé",IF($M$17="—","Sans objet (pas de note autonome)",IF(NOT(AND($F$25="Oui",$F$26="Oui",$F$27="Oui",$F$28="Oui")),"Refusé : les quatre conditions ne sont pas toutes documentées",IF(MIN($F$29,Paramètres!$C$15)=0,"Conditions remplies, aucun cran demandé","Relèvement de "&MIN($F$29,Paramètres!$C$15)&" cran(s)")))) -> Non demandé
B19: Exception NC04 — Dossier groupe incomplet alors que le groupe est matériel | E19: Non | F19: =IF($S$4=0,E19,INDEX('Cas exemples'!$D$17:$H$17,1,$S$4)) -> Non | I19: Conformité | M19: =IF($F$20="Oui","BLOQUÉ : aucune opération nouvelle ; note produite pour la surveillance",IF($F$21="Oui","Alerte à revoir par l'analyste","Aucun signal bloquant")) -> Aucun signal bloquant
B20: Red flag conformité bloquant (RF01, RF02, RF03, RF04) | E20: Non | F20: =IF($S$4=0,E20,INDEX('Cas exemples'!$D$18:$H$18,1,$S$4)) -> Non | I20: Contrôle : résultat du moteur de l'outil pour ce cas | M20: =IF($S$4=0,"(saisie libre : pas de référence)",INDEX('Cas exemples'!$D$123:$H$123,1,$S$4)&IFERROR(" — score "&FIXED(INDEX('Cas exemples'!$D$121:$H$121,1,$S$4),2),"")&IF(INDEX('Cas exemples'!$D$123:$H$123,1,$S$4)=IF($M$9="Aucun grade","—",$M$9)," ✔ concordant"," ✘ écart")) -> (saisie libre : pas de référence)
B21: Red flag à revoir (retards 31-89 j, covenant rompu, litige…) | E21: Non | F21: =IF($S$4=0,E21,INDEX('Cas exemples'!$D$19:$H$19,1,$S$4)) -> Non
B22: Défaut constaté (impayé > 90 j, restructuration, procédure) | E22: Non | F22: =IF($S$4=0,E22,INDEX('Cas exemples'!$D$20:$H$20,1,$S$4)) -> Non
B23: Grade de défaut (DEF1, DEF2, DEF3) | E23: DEF1 | F23: =IF($S$4=0,E23,INDEX('Cas exemples'!$D$21:$H$21,1,$S$4)) -> DEF1
B24: Support groupe demandé | E24: Non | F24: =IF($S$4=0,E24,INDEX('Cas exemples'!$D$22:$H$22,1,$S$4)) -> Non
B25: Support — capacité du garant documentée | E25: Non | F25: =IF($S$4=0,E25,INDEX('Cas exemples'!$D$23:$H$23,1,$S$4)) -> Non
B26: Support — volonté de soutien démontrée | E26: Non | F26: =IF($S$4=0,E26,INDEX('Cas exemples'!$D$24:$H$24,1,$S$4)) -> Non
B27: Support — engagement juridiquement contraignant | E27: Non | F27: =IF($S$4=0,E27,INDEX('Cas exemples'!$D$25:$H$25,1,$S$4)) -> Non
B28: Support — transférabilité des fonds établie | E28: Non | F28: =IF($S$4=0,E28,INDEX('Cas exemples'!$D$26:$H$26,1,$S$4)) -> Non
B29: Support — crans demandés (0 à 2) | E29: 0 | F29: =IF($S$4=0,E29,INDEX('Cas exemples'!$D$27:$H$27,1,$S$4)) -> 0
B32: 2. Critères — saisie et calcul
B33: Code | C33: Domaine | D33: Critère | E33: Type | F33: Unité | G33: Critique | H33: Statut saisi | I33: Valeur saisie | J33: Statut retenu | K33: Valeur retenue | L33: Score | M33: Poids nominal | N33: Poids effectif | O33: Poids observé | P33: Contribution | Q33: Barème ou repère retenu
B34: D1.1 | C34: D1 | D34: Croissance et stabilité du chiffre d'affaires | E34: Qualitatif | H34: Disponible | I34: 75 | J34: =IF($S$4=0,H34,INDEX('Cas exemples'!$D$28:$H$28,1,$S$4)) -> Disponible | K34: =IF($S$4=0,IF(I34="","",I34),IF(INDEX('Cas exemples'!$D$29:$H$29,1,$S$4)="","",INDEX('Cas exemples'!$D$29:$H$29,1,$S$4))) -> 75 | L34: =IF(Y34=1,"écarté",IF(X34=1,Paramètres!$C$5,K34)) -> 75 | M34: =INDEX(Grille!$H$5:$J$5,1,$S$5) -> 0.03 | N34: =IF(Y34=1,0,M34) -> 0.03 | O34: =IF(AND(J34="Disponible",X34=0),N34,0) -> 0.03 | P34: =IF(SUM($N$34:$N$78)=0,0,Z34/SUM($N$34:$N$78)) -> 2.25 | Q34: =IF(ISNUMBER(L34),IFERROR(INDEX(Grille!$X$5:$AB$5,1,MATCH(L34,{100,75,50,25,0},0)),""),"") -> CAGR 0 % à +3 % ou +20 % à +30 % ; une baisse ponctuelle ≤ 10 % expliquée et corrigée | X34: =IF(OR(J34="Manquante",K34=""),1,0) -> 0 | Y34: 0 | Z34: =IF(ISNUMBER(L34),L34*N34,0) -> 2.25
B35: D1.2 | C35: D1 | D35: Marge EBITDA / performance opérationnelle | E35: Qualitatif | H35: Disponible | I35: 75 | J35: =IF($S$4=0,H35,INDEX('Cas exemples'!$D$30:$H$30,1,$S$4)) -> Disponible | K35: =IF($S$4=0,IF(I35="","",I35),IF(INDEX('Cas exemples'!$D$31:$H$31,1,$S$4)="","",INDEX('Cas exemples'!$D$31:$H$31,1,$S$4))) -> 75 | L35: =IF(Y35=1,"écarté",IF(X35=1,Paramètres!$C$5,K35)) -> 75 | M35: =INDEX(Grille!$H$6:$J$6,1,$S$5) -> 0.04 | N35: =IF(Y35=1,0,M35) -> 0.04 | O35: =IF(AND(J35="Disponible",X35=0),N35,0) -> 0.04 | P35: =IF(SUM($N$34:$N$78)=0,0,Z35/SUM($N$34:$N$78)) -> 3 | Q35: =IF(ISNUMBER(L35),IFERROR(INDEX(Grille!$X$6:$AB$6,1,MATCH(L35,{100,75,50,25,0},0)),""),"") -> Marge entre P50 et P75, positive et stable à ±1 point | X35: =IF(OR(J35="Manquante",K35=""),1,0) -> 0 | Y35: 0 | Z35: =IF(ISNUMBER(L35),L35*N35,0) -> 3
B36: D1.3 | C36: D1 | D36: Rentabilité économique / ROA ajusté | E36: Qualitatif | H36: Disponible | I36: 50 | J36: =IF($S$4=0,H36,INDEX('Cas exemples'!$D$32:$H$32,1,$S$4)) -> Disponible | K36: =IF($S$4=0,IF(I36="","",I36),IF(INDEX('Cas exemples'!$D$33:$H$33,1,$S$4)="","",INDEX('Cas exemples'!$D$33:$H$33,1,$S$4))) -> 50 | L36: =IF(Y36=1,"écarté",IF(X36=1,Paramètres!$C$5,K36)) -> 50 | M36: =INDEX(Grille!$H$7:$J$7,1,$S$5) -> 0.03 | N36: =IF(Y36=1,0,M36) -> 0.03 | O36: =IF(AND(J36="Disponible",X36=0),N36,0) -> 0.03 | P36: =IF(SUM($N$34:$N$78)=0,0,Z36/SUM($N$34:$N$78)) -> 1.5 | Q36: =IF(ISNUMBER(L36),IFERROR(INDEX(Grille!$X$7:$AB$7,1,MATCH(L36,{100,75,50,25,0},0)),""),"") -> P25 à P50, faible mais positif, ou un exercice déficitaire non récurrent | X36: =IF(OR(J36="Manquante",K36=""),1,0) -> 0 | Y36: 0 | Z36: =IF(ISNUMBER(L36),L36*N36,0) -> 1.5
B37: D1.4 | C37: D1 | D37: Fonds propres tangibles / total bilan | E37: Ratio | F37: % | G37: Oui | H37: Disponible | I37: 38 | J37: =IF($S$4=0,H37,INDEX('Cas exemples'!$D$34:$H$34,1,$S$4)) -> Disponible | K37: =IF($S$4=0,IF(I37="","",I37),IF(INDEX('Cas exemples'!$D$35:$H$35,1,$S$4)="","",INDEX('Cas exemples'!$D$35:$H$35,1,$S$4))) -> 38 | L37: =IF(Y37=1,"écarté",IF(X37=1,Paramètres!$C$5,IF(W37="Croissant",IF(K37>=S37,100,IF(K37>=T37,75,IF(K37>=U37,50,IF(K37>=V37,25,0)))),IF(K37<=S37,100,IF(K37<=T37,75,IF(K37<=U37,50,IF(K37<=V37,25,0))))))) -> 100 | M37: =INDEX(Grille!$H$8:$J$8,1,$S$5) -> 0.05 | N37: =IF(Y37=1,0,M37) -> 0.05 | O37: =IF(AND(J37="Disponible",X37=0),N37,0) -> 0.05 | P37: =IF(SUM($N$34:$N$78)=0,0,Z37/SUM($N$34:$N$78)) -> 5 | Q37: =IF(W37="Croissant","100 si ≥ "&S37&" · 75 si ≥ "&T37&" · 50 si ≥ "&U37&" · 25 si ≥ "&V37&" · sinon 0","100 si ≤ "&S37&" · 75 si ≤ "&T37&" · 50 si ≤ "&U37&" · 25 si ≤ "&V37&" · sinon 0") -> 100 si ≥ 35 · 75 si ≥ 25 · 50 si ≥ 15 · 25 si ≥ 8 · sinon 0 | S37: =INDEX(Grille!$L$8:$W$8,1,($S$5-1)*4+1) -> 35 | T37: =INDEX(Grille!$L$8:$W$8,1,($S$5-1)*4+2) -> 25 | U37: =INDEX(Grille!$L$8:$W$8,1,($S$5-1)*4+3) -> 15 | V37: =INDEX(Grille!$L$8:$W$8,1,($S$5-1)*4+4) -> 8 | W37: =Grille!$K$8 -> Croissant | X37: =IF(OR(J37="Manquante",K37=""),1,0) -> 0 | Y37: 0 | Z37: =IF(ISNUMBER(L37),L37*N37,0) -> 5
B38: D1.5 | C38: D1 | D38: Dette financière nette / EBITDA ajusté | E38: Ratio | F38: x | G38: Oui | H38: Disponible | I38: 1.2 | J38: =IF($S$4=0,H38,INDEX('Cas exemples'!$D$36:$H$36,1,$S$4)) -> Disponible | K38: =IF($S$4=0,IF(I38="","",I38),IF(INDEX('Cas exemples'!$D$37:$H$37,1,$S$4)="","",INDEX('Cas exemples'!$D$37:$H$37,1,$S$4))) -> 1.2 | L38: =IF(Y38=1,"écarté",IF(X38=1,Paramètres!$C$5,IF(W38="Croissant",IF(K38>=S38,100,IF(K38>=T38,75,IF(K38>=U38,50,IF(K38>=V38,25,0)))),IF(K38<=S38,100,IF(K38<=T38,75,IF(K38<=U38,50,IF(K38<=V38,25,0))))))) -> 100 | M38: =INDEX(Grille!$H$9:$J$9,1,$S$5) -> 0.05 | N38: =IF(Y38=1,0,M38) -> 0.05 | O38: =IF(AND(J38="Disponible",X38=0),N38,0) -> 0.05 | P38: =IF(SUM($N$34:$N$78)=0,0,Z38/SUM($N$34:$N$78)) -> 5 | Q38: =IF(W38="Croissant","100 si ≥ "&S38&" · 75 si ≥ "&T38&" · 50 si ≥ "&U38&" · 25 si ≥ "&V38&" · sinon 0","100 si ≤ "&S38&" · 75 si ≤ "&T38&" · 50 si ≤ "&U38&" · 25 si ≤ "&V38&" · sinon 0") -> 100 si ≤ 1.5 · 75 si ≤ 2.5 · 50 si ≤ 3.5 · 25 si ≤ 5 · sinon 0 | S38: =INDEX(Grille!$L$9:$W$9,1,($S$5-1)*4+1) -> 1.5 | T38: =INDEX(Grille!$L$9:$W$9,1,($S$5-1)*4+2) -> 2.5 | U38: =INDEX(Grille!$L$9:$W$9,1,($S$5-1)*4+3) -> 3.5 | V38: =INDEX(Grille!$L$9:$W$9,1,($S$5-1)*4+4) -> 5 | W38: =Grille!$K$9 -> Décroissant | X38: =IF(OR(J38="Manquante",K38=""),1,0) -> 0 | Y38: 0 | Z38: =IF(ISNUMBER(L38),L38*N38,0) -> 5
B39: D1.6 | C39: D1 | D39: Liquidité court terme | E39: Ratio | F39: x | H39: Disponible | I39: 1.6 | J39: =IF($S$4=0,H39,INDEX('Cas exemples'!$D$38:$H$38,1,$S$4)) -> Disponible | K39: =IF($S$4=0,IF(I39="","",I39),IF(INDEX('Cas exemples'!$D$39:$H$39,1,$S$4)="","",INDEX('Cas exemples'!$D$39:$H$39,1,$S$4))) -> 1.6 | L39: =IF(Y39=1,"écarté",IF(X39=1,Paramètres!$C$5,IF(W39="Croissant",IF(K39>=S39,100,IF(K39>=T39,75,IF(K39>=U39,50,IF(K39>=V39,25,0)))),IF(K39<=S39,100,IF(K39<=T39,75,IF(K39<=U39,50,IF(K39<=V39,25,0))))))) -> 100 | M39: =INDEX(Grille!$H$10:$J$10,1,$S$5) -> 0.04 | N39: =IF(Y39=1,0,M39) -> 0.04 | O39: =IF(AND(J39="Disponible",X39=0),N39,0) -> 0.04 | P39: =IF(SUM($N$34:$N$78)=0,0,Z39/SUM($N$34:$N$78)) -> 4 | Q39: =IF(W39="Croissant","100 si ≥ "&S39&" · 75 si ≥ "&T39&" · 50 si ≥ "&U39&" · 25 si ≥ "&V39&" · sinon 0","100 si ≤ "&S39&" · 75 si ≤ "&T39&" · 50 si ≤ "&U39&" · 25 si ≤ "&V39&" · sinon 0") -> 100 si ≥ 1.5 · 75 si ≥ 1.25 · 50 si ≥ 1 · 25 si ≥ 0.8 · sinon 0 | S39: =INDEX(Grille!$L$10:$W$10,1,($S$5-1)*4+1) -> 1.5 | T39: =INDEX(Grille!$L$10:$W$10,1,($S$5-1)*4+2) -> 1.25 | U39: =INDEX(Grille!$L$10:$W$10,1,($S$5-1)*4+3) -> 1 | V39: =INDEX(Grille!$L$10:$W$10,1,($S$5-1)*4+4) -> 0.8 | W39: =Grille!$K$10 -> Croissant | X39: =IF(OR(J39="Manquante",K39=""),1,0) -> 0 | Y39: 0 | Z39: =IF(ISNUMBER(L39),L39*N39,0) -> 4
B40: D1.7 | C40: D1 | D40: BFR et cycle de conversion de trésorerie | E40: Qualitatif | H40: Disponible | I40: 50 | J40: =IF($S$4=0,H40,INDEX('Cas exemples'!$D$40:$H$40,1,$S$4)) -> Disponible | K40: =IF($S$4=0,IF(I40="","",I40),IF(INDEX('Cas exemples'!$D$41:$H$41,1,$S$4)="","",INDEX('Cas exemples'!$D$41:$H$41,1,$S$4))) -> 50 | L40: =IF(Y40=1,"écarté",IF(X40=1,Paramètres!$C$5,K40)) -> 50 | M40: =INDEX(Grille!$H$11:$J$11,1,$S$5) -> 0.03 | N40: =IF(Y40=1,0,M40) -> 0.03 | O40: =IF(AND(J40="Disponible",X40=0),N40,0) -> 0.03 | P40: =IF(SUM($N$34:$N$78)=0,0,Z40/SUM($N$34:$N$78)) -> 1.5 | Q40: =IF(ISNUMBER(L40),IFERROR(INDEX(Grille!$X$11:$AB$11,1,MATCH(L40,{100,75,50,25,0},0)),""),"") -> Entre P50 et P75 ou détérioration de 6 à 15 jours, financée sans dépassement | X40: =IF(OR(J40="Manquante",K40=""),1,0) -> 0 | Y40: 0 | Z40: =IF(ISNUMBER(L40),L40*N40,0) -> 1.5
B41: D1.8 | C41: D1 | D41: Conversion EBITDA en cash-flow opérationnel | E41: Ratio | F41: % | H41: Disponible | I41: 75 | J41: =IF($S$4=0,H41,INDEX('Cas exemples'!$D$42:$H$42,1,$S$4)) -> Disponible | K41: =IF($S$4=0,IF(I41="","",I41),IF(INDEX('Cas exemples'!$D$43:$H$43,1,$S$4)="","",INDEX('Cas exemples'!$D$43:$H$43,1,$S$4))) -> 75 | L41: =IF(Y41=1,"écarté",IF(X41=1,Paramètres!$C$5,IF(W41="Croissant",IF(K41>=S41,100,IF(K41>=T41,75,IF(K41>=U41,50,IF(K41>=V41,25,0)))),IF(K41<=S41,100,IF(K41<=T41,75,IF(K41<=U41,50,IF(K41<=V41,25,0))))))) -> 75 | M41: =INDEX(Grille!$H$12:$J$12,1,$S$5) -> 0.03 | N41: =IF(Y41=1,0,M41) -> 0.03 | O41: =IF(AND(J41="Disponible",X41=0),N41,0) -> 0.03 | P41: =IF(SUM($N$34:$N$78)=0,0,Z41/SUM($N$34:$N$78)) -> 2.25 | Q41: =IF(W41="Croissant","100 si ≥ "&S41&" · 75 si ≥ "&T41&" · 50 si ≥ "&U41&" · 25 si ≥ "&V41&" · sinon 0","100 si ≤ "&S41&" · 75 si ≤ "&T41&" · 50 si ≤ "&U41&" · 25 si ≤ "&V41&" · sinon 0") -> 100 si ≥ 90 · 75 si ≥ 70 · 50 si ≥ 50 · 25 si ≥ 20 · sinon 0 | S41: =INDEX(Grille!$L$12:$W$12,1,($S$5-1)*4+1) -> 90 | T41: =INDEX(Grille!$L$12:$W$12,1,($S$5-1)*4+2) -> 70 | U41: =INDEX(Grille!$L$12:$W$12,1,($S$5-1)*4+3) -> 50 | V41: =INDEX(Grille!$L$12:$W$12,1,($S$5-1)*4+4) -> 20 | W41: =Grille!$K$12 -> Croissant | X41: =IF(OR(J41="Manquante",K41=""),1,0) -> 0 | Y41: 0 | Z41: =IF(ISNUMBER(L41),L41*N41,0) -> 2.25
B42: D2.1 | C42: D2 | D42: Couverture des intérêts | E42: Ratio | F42: x | H42: Disponible | I42: 6 | J42: =IF($S$4=0,H42,INDEX('Cas exemples'!$D$44:$H$44,1,$S$4)) -> Disponible | K42: =IF($S$4=0,IF(I42="","",I42),IF(INDEX('Cas exemples'!$D$45:$H$45,1,$S$4)="","",INDEX('Cas exemples'!$D$45:$H$45,1,$S$4))) -> 6 | L42: =IF(Y42=1,"écarté",IF(X42=1,Paramètres!$C$5,IF(W42="Croissant",IF(K42>=S42,100,IF(K42>=T42,75,IF(K42>=U42,50,IF(K42>=V42,25,0)))),IF(K42<=S42,100,IF(K42<=T42,75,IF(K42<=U42,50,IF(K42<=V42,25,0))))))) -> 100 | M42: =INDEX(Grille!$H$13:$J$13,1,$S$5) -> 0.02 | N42: =IF(Y42=1,0,M42) -> 0.02 | O42: =IF(AND(J42="Disponible",X42=0),N42,0) -> 0.02 | P42: =IF(SUM($N$34:$N$78)=0,0,Z42/SUM($N$34:$N$78)) -> 2 | Q42: =IF(W42="Croissant","100 si ≥ "&S42&" · 75 si ≥ "&T42&" · 50 si ≥ "&U42&" · 25 si ≥ "&V42&" · sinon 0","100 si ≤ "&S42&" · 75 si ≤ "&T42&" · 50 si ≤ "&U42&" · 25 si ≤ "&V42&" · sinon 0") -> 100 si ≥ 5 · 75 si ≥ 3 · 50 si ≥ 2 · 25 si ≥ 1.2 · sinon 0 | S42: =INDEX(Grille!$L$13:$W$13,1,($S$5-1)*4+1) -> 5 | T42: =INDEX(Grille!$L$13:$W$13,1,($S$5-1)*4+2) -> 3 | U42: =INDEX(Grille!$L$13:$W$13,1,($S$5-1)*4+3) -> 2 | V42: =INDEX(Grille!$L$13:$W$13,1,($S$5-1)*4+4) -> 1.2 | W42: =Grille!$K$13 -> Croissant | X42: =IF(OR(J42="Manquante",K42=""),1,0) -> 0 | Y42: 0 | Z42: =IF(ISNUMBER(L42),L42*N42,0) -> 2
B43: D2.2 | C43: D2 | D43: DSCR / couverture du service de la dette | E43: Ratio | F43: x | H43: Disponible | I43: 1.7 | J43: =IF($S$4=0,H43,INDEX('Cas exemples'!$D$46:$H$46,1,$S$4)) -> Disponible | K43: =IF($S$4=0,IF(I43="","",I43),IF(INDEX('Cas exemples'!$D$47:$H$47,1,$S$4)="","",INDEX('Cas exemples'!$D$47:$H$47,1,$S$4))) -> 1.7 | L43: =IF(Y43=1,"écarté",IF(X43=1,Paramètres!$C$5,IF(W43="Croissant",IF(K43>=S43,100,IF(K43>=T43,75,IF(K43>=U43,50,IF(K43>=V43,25,0)))),IF(K43<=S43,100,IF(K43<=T43,75,IF(K43<=U43,50,IF(K43<=V43,25,0))))))) -> 100 | M43: =INDEX(Grille!$H$14:$J$14,1,$S$5) -> 0.04 | N43: =IF(Y43=1,0,M43) -> 0.04 | O43: =IF(AND(J43="Disponible",X43=0),N43,0) -> 0.04 | P43: =IF(SUM($N$34:$N$78)=0,0,Z43/SUM($N$34:$N$78)) -> 4 | Q43: =IF(W43="Croissant","100 si ≥ "&S43&" · 75 si ≥ "&T43&" · 50 si ≥ "&U43&" · 25 si ≥ "&V43&" · sinon 0","100 si ≤ "&S43&" · 75 si ≤ "&T43&" · 50 si ≤ "&U43&" · 25 si ≤ "&V43&" · sinon 0") -> 100 si ≥ 1.6 · 75 si ≥ 1.35 · 50 si ≥ 1.2 · 25 si ≥ 1 · sinon 0 | S43: =INDEX(Grille!$L$14:$W$14,1,($S$5-1)*4+1) -> 1.6 | T43: =INDEX(Grille!$L$14:$W$14,1,($S$5-1)*4+2) -> 1.35 | U43: =INDEX(Grille!$L$14:$W$14,1,($S$5-1)*4+3) -> 1.2 | V43: =INDEX(Grille!$L$14:$W$14,1,($S$5-1)*4+4) -> 1 | W43: =Grille!$K$14 -> Croissant | X43: =IF(OR(J43="Manquante",K43=""),1,0) -> 0 | Y43: 0 | Z43: =IF(ISNUMBER(L43),L43*N43,0) -> 4
...

Sheet Paramètres
B1: PARAMÈTRES DU MODÈLE
B2: Valeurs du modèle CORP_STD_V1 v3.0.0, reprises du moteur de l'outil. Modifiables pour tester une sensibilité : les cellules sur fond orangé sont utilisées par toutes les formules du simulateur.
B4: Paramètre | C4: Valeur | D4: Source et commentaire
B5: Score d'une donnée absente ou périmée (sur 100) | C5: 25 | D5: Score prudent du modèle (unavailableScore) ; point ouvert D-32 : peut améliorer un critère très mauvais.
B6: Couverture observée minimale — global | C6: 0.6 | D6: Part du poids portée par une donnée observée (statut Disponible).
B7: Couverture observée minimale — par domaine | C7: 0.3 | D7: Sous ce seuil dans un domaine, aucun grade n'est produit.
B8: Poids de la complétude dans la confiance | C8: 0.35 | D8: Classe de confiance : informative, ne modifie jamais le grade.
B9: Poids de la fraîcheur | C9: 0.2
B10: Poids de la fiabilité | C10: 0.3
B11: Poids de la provenance | C11: 0.15
B12: Confiance — seuil de la classe A | C12: 85 | D12: Élevée
B13: Confiance — seuil de la classe B | C13: 70 | D13: Moyenne
B14: Confiance — seuil de la classe C (minimum pour un grade) | C14: 55 | D14: Sous ce seuil (classe U) : aucun grade.
B15: Support groupe — crans maximum | C15: 2 | D15: Si les quatre conditions sont documentées.
B18: Échelle de grades du modèle standard
B19: Grade | C19: Score minimum | D19: Lecture
B20: STD-P1 | C20: 88 | D20: Très solide
B21: STD-P2 | C21: 82 | D21: Solide
B22: STD-P3 | C22: 76 | D22: Bon
B23: STD-P4 | C23: 70 | D23: Satisfaisant
B24: STD-P5 | C24: 64 | D24: Acceptable
B25: STD-P6 | C25: 57 | D25: Fragile
B26: STD-P7 | C26: 48 | D26: Faible
B27: STD-P8 | C27: 0 | D27: Très faible
B29: Exceptions non compensatoires (plafonds)
B30: Exception | C30: Grade plafond | D30: Situation
B31: NC01 | C31: STD-P7 | D31: Couverture du service de la dette inférieure à 1 en scénario de base
B32: NC02 | C32: STD-P7 | D32: Incertitude matérielle sur la continuité d'exploitation
B33: NC03 | C33: STD-P7 | D33: Excédent brut d'exploitation négatif deux années sur trois
B34: NC04 | C34: STD-P6 | D34: Dossier groupe incomplet alors que le groupe est matériel

Sheet Grille
B1: GRILLE DE NOTATION — 45 CRITÈRES
B2: Barèmes des ratios par segment et repères des critères qualitatifs, tels qu'appliqués par le moteur. Ratio « croissant » : plus la valeur est haute, meilleur est le score ; « décroissant » : l'inverse.
B4: Code | C4: Domaine | D4: Critère | E4: Type | F4: Unité | G4: Critique | H4: Poids TPE | I4: Poids PME | J4: Poids GE | K4: Sens | L4: TPE : 100 si | M4: TPE : 75 si | N4: TPE : 50 si | O4: TPE : 25 si | P4: PME : 100 si | Q4: PME : 75 si | R4: PME : 50 si | S4: PME : 25 si | T4: GE : 100 si | U4: GE : 75 si | V4: GE : 50 si | W4: GE : 25 si | X4: Repère 100 | Y4: Repère 75 | Z4: Repère 50 | AA4: Repère 25 | AB4: Repère 0
B5: D1.1 | C5: D1 | D5: Croissance et stabilité du chiffre d'affaires | E5: Qualitatif | H5: 0.03 | I5: 0.03 | J5: 0.03 | X5: CAGR +3 % à +20 %, aucune baisse annuelle > 10 %, volatilité faible, ≥ médiane sectorielle | Y5: CAGR 0 % à +3 % ou +20 % à +30 % ; une baisse ponctuelle ≤ 10 % expliquée et corrigée | Z5: CAGR −5 % à 0 %, ou > +30 % avec tension BFR maîtrisable, ou volatilité matérielle sans tendance durable | AA5: CAGR −15 % à −5 %, ou deux exercices consécutifs en baisse, ou écart défavorable au secteur > 10 points | AB5: CAGR < −15 %, effondrement récent > 25 %, perte majeure de clientèle ou CA non fiable
B6: D1.2 | C6: D1 | D6: Marge EBITDA / performance opérationnelle | E6: Qualitatif | H6: 0.03 | I6: 0.04 | J6: 0.04 | X6: Marge ≥ P75 sectoriel, positive sur trois ans et stable/améliorée de ≥ 1 point | Y6: Marge entre P50 et P75, positive et stable à ±1 point | Z6: Marge entre P25 et P50, ou baisse de 1 à 3 points en restant positive | AA6: Marge entre P10 et P25, ou baisse > 3 points, ou un exercice proche de zéro | AB6: Marge négative au dernier exercice, < P10, pertes opérationnelles récurrentes ou EBITDA non fiable
B7: D1.3 | C7: D1 | D7: Rentabilité économique / ROA ajusté | E7: Qualitatif | H7: 0.02 | I7: 0.03 | J7: 0.03 | X7: ≥ P75 sectoriel, positif sur trois ans, sans dépendance à un produit exceptionnel | Y7: P50 à P75, positif et stable | Z7: P25 à P50, faible mais positif, ou un exercice déficitaire non récurrent | AA7: P10 à P25, proche de zéro ou forte dépendance à des éléments non récurrents | AB7: Négatif au dernier exercice et tendance non corrigée, ou < P10 sur deux exercices
B8: D1.4 | C8: D1 | D8: Fonds propres tangibles / total bilan | E8: Ratio | F8: % | G8: Oui | H8: 0.04 | I8: 0.05 | J8: 0.04 | K8: Croissant | L8: 35 | M8: 25 | N8: 15 | O8: 5 | P8: 35 | Q8: 25 | R8: 15 | S8: 8 | T8: 30 | U8: 20 | V8: 12 | W8: 5
B9: D1.5 | C9: D1 | D9: Dette financière nette / EBITDA ajusté | E9: Ratio | F9: x | G9: Oui | H9: 0.04 | I9: 0.05 | J9: 0.05 | K9: Décroissant | L9: 1 | M9: 2 | N9: 3.5 | O9: 5 | P9: 1.5 | Q9: 2.5 | R9: 3.5 | S9: 5 | T9: 1.5 | U9: 2.5 | V9: 3.5 | W9: 4.5
B10: D1.6 | C10: D1 | D10: Liquidité court terme | E10: Ratio | F10: x | H10: 0.04 | I10: 0.04 | J10: 0.03 | K10: Croissant | L10: 1.5 | M10: 1.25 | N10: 1 | O10: 0.8 | P10: 1.5 | Q10: 1.25 | R10: 1 | S10: 0.8 | T10: 1.4 | U10: 1.2 | V10: 1 | W10: 0.85
B11: D1.7 | C11: D1 | D11: BFR et cycle de conversion de trésorerie | E11: Qualitatif | H11: 0.03 | I11: 0.03 | J11: 0.03 | X11: Cycle ≤ P25 sectoriel, stable ou amélioré ; aucune tension fournisseur | Y11: Entre P25 et P50 ; détérioration ≤ 5 jours | Z11: Entre P50 et P75 ou détérioration de 6 à 15 jours, financée sans dépassement | AA11: > P75 ou détérioration de 16 à 45 jours ; stocks/créances vieillissants | AB11: > P90 avec détérioration > 45 jours, actifs non recouvrables, fournisseurs durablement impayés ou BFR non finançable
B12: D1.8 | C12: D1 | D12: Conversion EBITDA en cash-flow opérationnel | E12: Ratio | F12: % | H12: 0.02 | I12: 0.03 | J12: 0.05 | K12: Croissant | L12: 90 | M12: 70 | N12: 50 | O12: 20 | P12: 90 | Q12: 70 | R12: 50 | S12: 20 | T12: 90 | U12: 70 | V12: 50 | W12: 20
B13: D2.1 | C13: D2 | D13: Couverture des intérêts | E13: Ratio | F13: x | H13: 0.015 | I13: 0.02 | J13: 0.03 | K13: Croissant | L13: 5 | M13: 3 | N13: 2 | O13: 1 | P13: 5 | Q13: 3 | R13: 2 | S13: 1.2 | T13: 6 | U13: 4 | V13: 2.5 | W13: 1.5
B14: D2.2 | C14: D2 | D14: DSCR / couverture du service de la dette | E14: Ratio | F14: x | H14: 0.03 | I14: 0.04 | J14: 0.05 | K14: Croissant | L14: 1.5 | M14: 1.3 | N14: 1.15 | O14: 1 | P14: 1.6 | Q14: 1.35 | R14: 1.2 | S14: 1 | T14: 1.75 | U14: 1.4 | V14: 1.2 | W14: 1
B15: D2.3 | C15: D2 | D15: Free cash-flow / dette financière | E15: Ratio | F15: % | H15: 0.01 | I15: 0.02 | J15: 0.03 | K15: Croissant | L15: 20 | M15: 12 | N15: 5 | O15: 0 | P15: 20 | Q15: 12 | R15: 5 | S15: 0 | T15: 20 | U15: 12 | V15: 5 | W15: 0
B16: D2.4 | C16: D2 | D16: Liquidité disponible et mur de dette | E16: Qualitatif | H16: 0.015 | I16: 0.02 | J16: 0.03 | X16: Couverture ≥ 12 mois, headroom ≥ 30 %, aucune échéance concentrée non financée | Y16: Couverture 9–12 mois, headroom 20–30 %, refinancement très probable et documenté | Z16: Couverture 6–9 mois, headroom 10–20 %, dépendance modérée au renouvellement | AA16: Couverture 3–6 mois, headroom < 10 %, mur de dette proche ou lignes non confirmées | AB16: Couverture < 3 mois, gap avéré, refinancement non sécurisé ou rupture prévisible
B17: D2.5 | C17: D2 | D17: Résistance au scénario de stress | E17: Ratio | F17: x | H17: 0.02 | I17: 0.03 | J17: 0.04 | K17: Croissant | L17: 1.4 | M17: 1.2 | N17: 1 | O17: 0.8 | P17: 1.4 | Q17: 1.2 | R17: 1 | S17: 0.8 | T17: 1.4 | U17: 1.2 | V17: 1 | W17: 0.8
B18: D2.6 | C18: D2 | D18: Covenants et marge de sécurité | E18: Qualitatif | H18: 0.01 | I18: 0.02 | J18: 0.02 | X18: Aucun covenant financier ou marge ≥ 30 % sur tous les covenants ; reporting à jour | Y18: Marge entre 20 % et 30 % ; aucune tendance de rupture | Z18: Marge entre 10 % et 20 % ou waiver ancien régularisé | AA18: Marge entre 0 % et 10 %, waiver en cours ou reporting incomplet | AB18: Covenant rompu non régularisé, information dissimulée ou accélération possible de dette
B19: D3.1 | C19: D3 | D19: Retards de paiement / DPD | E19: Ratio | F19: j | G19: Oui | H19: 0.06 | I19: 0.05 | J19: 0.025 | K19: Décroissant | L19: 0 | M19: 7 | N19: 30 | O19: 60 | P19: 0 | Q19: 7 | R19: 30 | S19: 60 | T19: 0 | U19: 7 | V19: 30 | W19: 60
B20: D3.2 | C20: D3 | D20: Dépassements et irrégularités de compte | E20: Qualitatif | H20: 0.04 | I20: 0.03 | J20: 0.015 | X20: Aucun dépassement non autorisé | Y20: Un dépassement ≤ 3 jours et ≤ 5 % de la ligne, régularisé spontanément | Z20: 4–15 jours cumulés ou 2–3 épisodes, montant ≤ 10 % de la ligne | AA20: 16–30 jours cumulés, épisodes mensuels ou montant > 10 % | AB20: > 30 jours, dépassement permanent, compte bloqué ou absence d'autorisation
B21: D3.3 | C21: D3 | D21: Utilisation des lignes | E21: Qualitatif | H21: 0.03 | I21: 0.02 | J21: 0.01 | X21: Utilisation moyenne 20–70 %, pics cohérents avec la saisonnalité, marge disponible | Y21: 10–20 % ou 70–85 %, utilisation stable et justifiée | Z21: 85–95 %, ou hausse > 20 points sur six mois, sans dépassement | AA21: > 95 % pendant plus de trois mois, pics fréquents ou dépendance au renouvellement | AB21: > 100 % non autorisé, ligne saturée sans capacité de réduction ou besoin structurel non financé
B22: D3.4 | C22: D3 | D22: Mouvements créditeurs et domiciliation | E22: Ratio | F22: % | H22: 0.04 | I22: 0.03 | J22: 0.015 | K22: Croissant | L22: 110 | M22: 90 | N22: 70 | O22: 50 | P22: 110 | Q22: 90 | R22: 70 | S22: 50 | T22: 110 | U22: 90 | V22: 70 | W22: 50
B23: D3.5 | C23: D3 | D23: Incidents chèques et effets de commerce | E23: Qualitatif | H23: 0.04 | I23: 0.03 | J23: 0.01 | X23: Absence d'incident vérifiée auprès des sources autorisées | Y23: Un incident mineur, erreur technique démontrée, régularisé ≤ 5 jours | Z23: Un à deux incidents régularisés ≤ 30 jours, montant non matériel | AA23: Incidents récurrents, régularisation tardive ou incident matériel | AB23: Incident grave/non régularisé, interdiction ou signal bloquant selon dispositif applicable
B24: D3.6 | C24: D3 | D24: Restructuration et forbearance | E24: Qualitatif | H24: 0.02 | I24: 0.02 | J24: 0.015 | X24: Aucune restructuration ni concession liée à une difficulté financière | Y24: Restructuration ancienne > 36 mois, période probatoire achevée, performance durable | Z24: Restructuration entre 24 et 36 mois, paiements réguliers, surveillance en cours | AA24: Restructuration < 24 mois, concession significative ou dépendance à un moratoire | AB24: Échec de restructuration, seconde concession, impayé post-restructuration ou défaut
B25: D3.7 | C25: D3 | D25: Tendance de l'endettement système et groupe | E25: Qualitatif | H25: 0.02 | I25: 0.02 | J25: 0.01 | X25: Endettement stable/en baisse, aucun incident groupe, capacité consolidée confortable | Y25: Hausse ≤ 10 % cohérente avec croissance et cash-flow | Z25: Hausse de 10–25 %, nouvelle banque/ligne ou concentration accrue mais justifiée | AA25: Hausse > 25 %, dette non expliquée, multiplication de demandes ou dégradation d'une entité liée | AB25: Cross-default, contagion applicable, dette cachée, incident majeur groupe ou soutien inversé non soutenable
B26: D4.1 | C26: D4 | D26: Risque sectoriel interne | E26: Qualitatif | H26: 0.03 | I26: 0.03 | J26: 0.03 | X26: S1 — secteur très résilient | Y26: S2 — secteur résilient | Z26: S3 — secteur moyen/cyclique maîtrisable | AA26: S4 — secteur vulnérable/sous surveillance | AB26: S5 — secteur très vulnérable/crise structurelle
B27: D4.2 | C27: D4 | D27: Position concurrentielle | E27: Qualitatif | H27: 0.02 | I27: 0.025 | J27: 0.03 | X27: Leader ou niche dominante ; avantages défendables ; pouvoir de prix ; preuves de parts de marché | Y27: Position forte ; différenciation claire ; bonne fidélité ; marges au moins sectorielles | Z27: Position moyenne ; offre comparable au marché ; pression concurrentielle normale | AA27: Position faible ; perte de parts/clients ; pression prix élevée ; dépendance à un canal | AB27: Position marginale/non viable ; produit obsolète ; rupture de licence ; perte du marché essentiel
B28: D4.3 | C28: D4 | D28: Concentration clients | E28: Ratio | F28: % | H28: 0.025 | I28: 0.02 | J28: 0.015 | K28: Décroissant | L28: 15 | M28: 25 | N28: 35 | O28: 50 | P28: 10 | Q28: 20 | R28: 30 | S28: 45 | T28: 10 | U28: 15 | V28: 25 | W28: 40
B29: D4.4 | C29: D4 | D29: Concentration fournisseurs | E29: Ratio | F29: % | H29: 0.02 | I29: 0.015 | J29: 0.015 | K29: Décroissant | L29: 15 | M29: 25 | N29: 40 | O29: 60 | P29: 15 | Q29: 25 | R29: 40 | S29: 60 | T29: 15 | U29: 25 | V29: 40 | W29: 60
B30: D4.5 | C30: D4 | D30: Visibilité des revenus / carnet de commandes | E30: Qualitatif | H30: 0.02 | I30: 0.02 | J30: 0.02 | X30: ≥ 12 mois de revenus sécurisés ou > 80 % récurrents avec rétention > 90 % ; contreparties solides | Y30: 9–12 mois ou 60–80 % récurrents ; annulations historiques faibles | Z30: 6–9 mois ou 40–60 % récurrents ; visibilité moyenne cohérente au secteur | AA30: 3–6 mois, carnet non ferme, churn élevé ou dépendance à appels d'offres non acquis | AB30: < 3 mois, annulations matérielles, carnet artificiel ou arrêt d'activité prévisible
B31: D4.6 | C31: D4 | D31: Exposition pays, change et matières premières | E31: Qualitatif | H31: 0.01 | I31: 0.015 | J31: 0.015 | X31: Exposition nette < 10 % de l'EBITDA ou couverture complète ; pays stables | Y31: Exposition 10–25 %, couverture > 75 %, répercussion prix démontrée | Z31: Exposition 25–50 %, couverture 50–75 %, volatilité absorbable | AA31: Exposition 50–100 %, couverture < 50 %, risque pays/transfert ou commodity matériel | AB31: Exposition > 100 % de l'EBITDA, aucune couverture, continuité menacée ou pays bloqué
B32: D4.7 | C32: D4 | D32: Risque opérationnel, technologie et capex | E32: Qualitatif | H32: 0.015 | I32: 0.015 | J32: 0.015 | X32: Processus robustes, redondance, maintenance et assurance adéquates, capex financé, aucun incident matériel | Y32: Contrôles satisfaisants, dépendances connues et plans testés, capex maîtrisé | Z32: Contrôles moyens, quelques dépendances/sites uniques, capex nécessaire mais finançable | AA32: Outil vieillissant, incidents fréquents, sous-investissement, dépendance critique, assurance insuffisante | AB32: Arrêt majeur non résolu, technologie obsolète, perte de licence/certification ou capex vital non financé
B33: D4.8 | C33: D4 | D33: Qualité et soutenabilité de la croissance | E33: Qualitatif | H33: 0.01 | I33: 0.01 | J33: 0.01 | X33: Croissance rentable, financée majoritairement par cash-flow/fonds propres, BFR et capacités maîtrisés | Y33: Croissance rentable avec dette modérée, plan capacitaire et commercial prouvé | Z33: Croissance correcte mais dépendante de dette/BFR ; hypothèses raisonnables, mitigations identifiées | AA33: Croissance non rentable, BFR tendu, expansion trop rapide ou investissements sous-estimés | AB33: Croissance artificielle/circulaire, acquisitions non intégrées, destruction de cash ou plan irréaliste
B34: D5.1 | C34: D5 | D34: Expérience et stabilité du management | E34: Qualitatif | H34: 0.03 | I34: 0.025 | J34: 0.025 | X34: Équipe complète, > 10 ans d'expérience pertinente, stabilité > 5 ans, succession en place, réalisations vérifiées | Y34: Expérience 5–10 ans, faible turnover, compétences adaptées et résultats cohérents | Z34: Expérience 3–5 ans ou changement récent maîtrisé ; quelques lacunes compensées | AA34: Équipe incomplète, turnover élevé, expérience limitée, objectifs régulièrement non atteints | AB34: Incompétence manifeste, départs critiques, information trompeuse ou incapacité à exploiter
B35: D5.2 | C35: D5 | D35: Dépendance homme-clé et succession | E35: Qualitatif | H35: 0.025 | I35: 0.015 | J35: 0.015 | X35: Responsabilités distribuées, délégations formelles, successeurs identifiés et plan testé | Y35: Dépendance limitée ; adjoint compétent et documentation suffisante | Z35: Dépendance réelle mais remplaçable en 3–6 mois ; plan partiel | AA35: Dirigeant concentre clients, technique et pouvoirs ; absence de succession crédible | AB35: Indisponibilité de l'homme-clé compromettant immédiatement l'activité, sans solution
B36: D5.3 | C36: D5 | D36: Gouvernance et contrôle interne | E36: Qualitatif | H36: 0.02 | I36: 0.02 | J36: 0.03 | X36: Organes actifs et documentés, séparation des pouvoirs, audit/risques/conformité proportionnés | Y36: Gouvernance structurée, contrôles réguliers, incidents corrigés dans les délais | Z36: Gouvernance informelle mais fonctionnelle ; contrôles essentiels présents | AA36: Pouvoirs concentrés, contrôles faibles, recommandations récurrentes non clôturées | AB36: Absence de contrôle, fraude/irrégularité de gouvernance, décisions non autorisées
B37: D5.4 | C37: D5 | D37: Actionnariat, groupe et soutien | E37: Qualitatif | H37: 0.02 | I37: 0.015 | J37: 0.025 | X37: Actionnariat stable et transparent ; parent très solide ; support juridiquement engageant ou historique incontestable | Y37: Actionnaires solides et impliqués ; soutien documenté mais non totalement contraignant | Z37: Actionnariat stable, capacité de soutien moyenne ou entité autonome sans besoin de support | AA37: Conflits, dilution probable, actionnaires endettés ou soutien incertain | AB37: Groupe en difficulté, ponctions de cash, litige actionnarial majeur ou opacité
B38: D5.5 | C38: D5 | D38: Stratégie et qualité d'exécution | E38: Qualitatif | H38: 0.02 | I38: 0.015 | J38: 0.02 | X38: Stratégie documentée et cohérente ; réalisations ≥ 90 % des budgets ajustés | Y38: Stratégie crédible ; réalisations 75–90 % ; écarts expliqués et corrigés | Z38: Plan raisonnable mais partiellement documenté ; réalisations 60–75 % | AA38: Plans fréquemment révisés, réalisations < 60 %, hypothèses trop optimistes | AB38: Absence de stratégie, budgets manipulés ou décisions menaçant la continuité
B39: D5.6 | C39: D5 | D39: Transactions avec parties liées | E39: Qualitatif | H39: 0.015 | I39: 0.015 | J39: 0.015 | X39: Transactions limitées, aux conditions de marché, approuvées, documentées et rapprochées | Y39: Transactions significatives mais transparentes, contractuelles et recouvrées normalement | Z39: Transactions fréquentes, documentation partielle, impact financier limité | AA39: Créances/avances importantes, prix non démontrés, cash-pooling défavorable | AB39: Détournement de ressources, créances irrécouvrables, garanties cachées ou transactions non autorisées
B40: D5.7 | C40: D5 | D40: Pilotage financier et culture du risque | E40: Qualitatif | H40: 0.02 | I40: 0.015 | J40: 0.02 | X40: Reporting mensuel fiable, cash forecast glissant, scénarios, limites et alertes formalisés | Y40: Reporting trimestriel fiable, budget/forecast et suivi de trésorerie réguliers | Z40: Reporting annuel/intermédiaire suffisant mais peu prospectif ; dépendance à l'expert-comptable | AA40: Pilotage tardif, absence de forecast, données contradictoires, réaction après incident | AB40: Aucun pilotage fiable, refus de transparence ou dissimulation de difficultés
B41: D6.1 | C41: D6 | D41: Qualité / certification des états financiers | E41: Qualitatif | H41: 0.015 | I41: 0.0125 | J41: 0.015 | X41: Comptes audités/certifiés sans réserve matérielle ; ou TPE non soumise avec comptes rapprochés à fiabilité élevée | Y41: Opinion avec réserve non matérielle ou revue limitée solide ; écarts corrigés | Z41: Comptes non audités mais cohérents, documentés et rapprochés ; qualité moyenne | AA41: Réserves matérielles, nombreux retraitements ou périmètre incomplet | AB41: Comptes non fiables/refusés, soupçon de falsification ou continuité non reflétée
...

Sheet Cas exemples
B1: CAS EXEMPLES — ENTREPRISES FICTIVES
B2: Saisies des cas présentés au management. Choisissez un cas dans le simulateur (cellule « Cas chargé ») pour le rejouer ; la dernière partie donne le résultat calculé par le moteur de l'outil, pour contrôle.
B4: Clé | C4: Saisie | D4: A — Atlas Agro SA | E4: B — Souss Négoce SARL | F4: C — Tanger Logistique SA | G4: D — Rif Bâtiment SARL | H4: E — Fès Textile SA
B5: profil | C5: Profil | D5: PME agro-industrielle saine : fonds propres solides, endettement modéré, compte sans incident. | E5: Comptes corrects, mais compte courant tendu : retards de 20 jours, dépassements, incidents d'effets. | F5: Score correct, mais service de la dette non couvert en scénario de base (DSCR 0,9) : exception non compensatoire. | G5: Dossier incomplet : comptes partiels, comportement bancaire et activité non documentés. | H5: Impayé de plus de 90 jours constaté : le défaut s'impose, quel que soit le score.
B6: nom | C6: Contrepartie | D6: Atlas Agro SA | E6: Souss Négoce SARL | F6: Tanger Logistique SA | G6: Rif Bâtiment SARL | H6: Fès Textile SA
B7: segment | C7: Segment | D7: PME | E7: PME | F7: PME | G7: PME | H7: PME
B8: mat_phys | C8: Risque climatique physique matériel | D8: Oui | E8: Non | F8: Non | G8: Non | H8: Non
B9: mat_trans | C9: Risque de transition matériel | D9: Non | E9: Non | F9: Non | G9: Non | H9: Non
B10: conf_comp | C10: Confiance — complétude | D10: 100 | E10: 100 | F10: 100 | G10: 50 | H10: 100
B11: conf_fresh | C11: Confiance — fraîcheur | D11: 100 | E11: 100 | F11: 100 | G11: 75 | H11: 100
B12: conf_rel | C12: Confiance — fiabilité | D12: 75 | E12: 75 | F12: 75 | G12: 75 | H12: 75
B13: conf_prov | C13: Confiance — provenance | D13: 75 | E13: 75 | F13: 75 | G13: 75 | H13: 75
B14: NC01 | C14: NC01 — Couverture du service de la dette inférieure à 1 en scénario de base | D14: Non | E14: Non | F14: Oui | G14: Non | H14: Non
B15: NC02 | C15: NC02 — Incertitude matérielle sur la continuité d'exploitation | D15: Non | E15: Non | F15: Non | G15: Non | H15: Non
B16: NC03 | C16: NC03 — Excédent brut d'exploitation négatif deux années sur trois | D16: Non | E16: Non | F16: Non | G16: Non | H16: Non
B17: NC04 | C17: NC04 — Dossier groupe incomplet alors que le groupe est matériel | D17: Non | E17: Non | F17: Non | G17: Non | H17: Non
B18: rf_block | C18: Red flag conformité bloquant (RF01, RF02, RF03, RF04) | D18: Non | E18: Non | F18: Non | G18: Non | H18: Non
B19: rf_refer | C19: Red flag à revoir (alerte ou contrôle de défaut) | D19: Non | E19: Oui | F19: Non | G19: Non | H19: Oui
B20: default | C20: Défaut constaté | D20: Non | E20: Non | F20: Non | G20: Non | H20: Oui
B21: def_grade | C21: Grade de défaut | D21: DEF1 | E21: DEF1 | F21: DEF1 | G21: DEF1 | H21: DEF1
B22: gs_claim | C22: Support groupe demandé | D22: Non | E22: Non | F22: Non | G22: Non | H22: Non
B23: gs_cap | C23: Capacité du garant documentée | D23: Non | E23: Non | F23: Non | G23: Non | H23: Non
B24: gs_will | C24: Volonté de soutien démontrée | D24: Non | E24: Non | F24: Non | G24: Non | H24: Non
B25: gs_legal | C25: Engagement juridiquement contraignant | D25: Non | E25: Non | F25: Non | G25: Non | H25: Non
B26: gs_funds | C26: Transférabilité des fonds établie | D26: Non | E26: Non | F26: Non | G26: Non | H26: Non
B27: gs_notch | C27: Crans demandés | D27: 0 | E27: 0 | F27: 0 | G27: 0 | H27: 0
B28: S_D1.1 | C28: D1.1 — statut | D28: Disponible | E28: Disponible | F28: Disponible | G28: Manquante | H28: Disponible
B29: V_D1.1 | C29: D1.1 — valeur (score 0-100) | D29: 75 | E29: 75 | F29: 75 | H29: 75
B30: S_D1.2 | C30: D1.2 — statut | D30: Disponible | E30: Disponible | F30: Disponible | G30: Manquante | H30: Disponible
B31: V_D1.2 | C31: D1.2 — valeur (score 0-100) | D31: 75 | E31: 50 | F31: 50 | H31: 50
B32: S_D1.3 | C32: D1.3 — statut | D32: Disponible | E32: Disponible | F32: Disponible | G32: Manquante | H32: Disponible
B33: V_D1.3 | C33: D1.3 — valeur (score 0-100) | D33: 50 | E33: 50 | F33: 50 | H33: 50
B34: S_D1.4 | C34: D1.4 — statut | D34: Disponible | E34: Disponible | F34: Disponible | G34: Disponible | H34: Disponible
B35: V_D1.4 | C35: D1.4 — valeur (%) | D35: 38 | E35: 30 | F35: 30 | G35: 30 | H35: 30
B36: S_D1.5 | C36: D1.5 — statut | D36: Disponible | E36: Disponible | F36: Disponible | G36: Disponible | H36: Disponible
B37: V_D1.5 | C37: D1.5 — valeur (x) | D37: 1.2 | E37: 2.2 | F37: 2.2 | G37: 2.2 | H37: 2.2
B38: S_D1.6 | C38: D1.6 — statut | D38: Disponible | E38: Disponible | F38: Disponible | G38: Manquante | H38: Disponible
B39: V_D1.6 | C39: D1.6 — valeur (x) | D39: 1.6 | E39: 1.3 | F39: 1.3 | H39: 1.3
B40: S_D1.7 | C40: D1.7 — statut | D40: Disponible | E40: Disponible | F40: Disponible | G40: Manquante | H40: Disponible
B41: V_D1.7 | C41: D1.7 — valeur (score 0-100) | D41: 50 | E41: 50 | F41: 50 | H41: 50
...
